Workbook

Sheet DETALLE MF
A1: Sucursal | B1: Cajero | C1: Marca | D1: Marca herramienta | E1: Fecha descarga arqueo | F1: Fecha Arqueo | G1: Hora Arqueo | H1: Efectivo Arqueado /Arqueo fisico saldo contadores | I1: Saldo Contable | J1: dispensado_corte_arqueo | K1: recibido_corte_arqueo | L1: Remanente /Provisión /Ajustes | M1: Diferencia | N1: Naturaleza | O1: Gestión a Realizar | P1: Documento responsable
A2: 4 | B2: 316 | C2: =VLOOKUP(B2,'Lista MF'!B:C,2,0) -> BELLTECH | D2: BELLTECH | E2: 46084 | F2: 46083 | G2: 14:01:00 | H2: 165401700 | I2: 152849650 | J2: 10330000 | K2: 30416000 | L2: =1660000+2920000+2690000 -> 7270000 | M2: =I2-(H2+J2-K2)-L2 -> 263950 | N2: =IF(M2="","",IF(M2=0,"Cuadrado",IF(M2>0,"Faltante","Sobrante"))) -> Faltante | O2: ACLARAR DIFERENCIA Y REPETIR EL ARQUEO | P2: 71278620
A3: 4 | B3: 8630 | C3: =VLOOKUP(B3,'Lista MF'!B:C,2,0) -> BELLTECH | D3: BELLTECH | E3: 46084 | F3: 46083 | G3: 08:57:00 | H3: 340986350 | I3: 309933350 | J3: 1640000 | K3: 32693000 | M3: =I3-(H3+J3-K3)-L3 -> 0 | N3: =IF(M3="","",IF(M3=0,"Cuadrado",IF(M3>0,"Faltante","Sobrante"))) -> Cuadrado | O3: Cajero cuadrado, sin observación por parte de la sucursal | P3: 71278620
A4: 4 | B4: 8631 | C4: =VLOOKUP(B4,'Lista MF'!B:C,2,0) -> BELLTECH | D4: BELLTECH | E4: 46084 | F4: 46083 | G4: 11:06:00 | H4: 212123550 | I4: 170623550 | J4: 15550000 | K4: 57050000 | M4: =I4-(H4+J4-K4)-L4 -> 0 | N4: =IF(M4="","",IF(M4=0,"Cuadrado",IF(M4>0,"Faltante","Sobrante"))) -> Cuadrado | O4: Cajero cuadrado, sin observación por parte de la sucursal | P4: 71278620
A5: 5 | B5: 4866 | C5: =VLOOKUP(B5,'Lista MF'!B:C,2,0) -> DIEBOLD | D5: BELLTECH | E5: 46084 | F5: 46083 | G5: 15:26:24 | H5: 204655550 | I5: 144824400 | J5: 9970000 | K5: 69703150 | M5: =I5-(H5+J5-K5)-L5 -> -98000 | N5: =IF(M5="","",IF(M5=0,"Cuadrado",IF(M5>0,"Faltante","Sobrante"))) -> Sobrante | O5: La diferencia es contabilizada por la Gerencia De Autoservicios y Efectivo de manera centralizada a la cuenta de sobrantes 279510020 el 03/03/2026 | P5: 43824478
A6: 7 | B6: 5059 | C6: =VLOOKUP(B6,'Lista MF'!B:C,2,0) -> BELLTECH | D6: BELLTECH | E6: 46084 | F6: 46083 | G6: 08:46:00 | H6: 198375050 | I6: 200485150 | J6: 7370000 | K6: 0 | M6: =I6-(H6+J6-K6)-L6 -> -5259900 | N6: =IF(M6="","",IF(M6=0,"Cuadrado",IF(M6>0,"Faltante","Sobrante"))) -> Sobrante | O6: La diferencia es contabilizada por la Gerencia De Autoservicios y Efectivo de manera centralizada a la cuenta de sobrantes 279510020 el 03/03/2026 | P6: 1017155472
A7: 7 | B7: 7812 | C7: =VLOOKUP(B7,'Lista MF'!B:C,2,0) -> DIEBOLD | D7: BELLTECH | E7: 46084 | F7: 46083 | G7: 09:25:00 | H7: 69564800 | I7: 77472800 | J7: 4500000 | K7: 4955000 | L7: 8363000 | M7: =I7-(H7+J7-K7)-L7 -> 0 | N7: =IF(M7="","",IF(M7=0,"Cuadrado",IF(M7>0,"Faltante","Sobrante"))) -> Cuadrado | O7: Cajero cuadrado, sin observación por parte de la sucursal | P7: 1017155472
A8: 15 | B8: 8578 | C8: =VLOOKUP(B8,'Lista MF'!B:C,2,0) -> BELLTECH | D8: BELLTECH | E8: 46084 | F8: 46083 | G8: 15:28:00 | H8: 37305450 | I8: 53765450 | J8: 45750000 | K8: 28525000 | M8: =I8-(H8+J8-K8)-L8 -> -765000 | N8: =IF(M8="","",IF(M8=0,"Cuadrado",IF(M8>0,"Faltante","Sobrante"))) -> Sobrante | O8: La diferencia es contabilizada por la Gerencia De Autoservicios y Efectivo de manera centralizada a la cuenta de sobrantes 279510020 el 03/03/2026 | P8: 1037325417
A9: 33 | B9: 8861 | C9: =VLOOKUP(B9,'Lista MF'!B:C,2,0) -> BELLTECH | D9: BELLTECH | E9: 46084 | F9: 46083 | G9: 11:23:00 | H9: 134901800 | I9: 168074400 | J9: 23520000 | K9: 11607400 | M9: =I9-(H9+J9-K9)-L9 -> 21260000 | N9: =IF(M9="","",IF(M9=0,"Cuadrado",IF(M9>0,"Faltante","Sobrante"))) -> Faltante | O9: La diferencia es contabilizada por la Gerencia De Autoservicios y Efectivo de manera centralizada a la cuenta de faltantes 168710093 el 03/03/2026, esta diferencia ingresa a proceso de investigación en el área para identificar a que corresponde. | P9: 79659379
A10: 54 | B10: 6204 | C10: =VLOOKUP(B10,'Lista MF'!B:C,2,0) -> BELLTECH | D10: BELLTECH | E10: 46084 | F10: 46083 | G10: 09:43:00 | H10: 240573750 | I10: 241908750 | J10: 3880000 | K10: 0 | M10: =I10-(H10+J10-K10)-L10 -> -2545000 | N10: =IF(M10="","",IF(M10=0,"Cuadrado",IF(M10>0,"Faltante","Sobrante"))) -> Sobrante | O10: La diferencia es contabilizada por la Gerencia De Autoservicios y Efectivo de manera centralizada a la cuenta de sobrantes 279510020 el 03/03/2026 | P10: 1019068822
A11: 60 | B11: 8729 | C11: =VLOOKUP(B11,'Lista MF'!B:C,2,0) -> BELLTECH | D11: BELLTECH | E11: 46084 | F11: 46083 | G11: 10:41:00 | H11: 43414250 | I11: 32468250 | J11: 18200000 | K11: 29196000 | L11: 50000 | M11: =I11-(H11+J11-K11)-L11 -> 0 | N11: =IF(M11="","",IF(M11=0,"Cuadrado",IF(M11>0,"Faltante","Sobrante"))) -> Cuadrado | O11: Cajero cuadrado, sin observación por parte de la sucursal | P11: 14697128
A12: 61 | B12: 788 | C12: =VLOOKUP(B12,'Lista MF'!B:C,2,0) -> BELLTECH | D12: DIEBOLD | E12: 46084 | F12: 46083 | G12: 09:45:00 | H12: 149527500 | I12: 155897500 | J12: 16070000 | K12: 9900000 | M12: =I12-(H12+J12-K12)-L12 -> 200000 | N12: =IF(M12="","",IF(M12=0,"Cuadrado",IF(M12>0,"Faltante","Sobrante"))) -> Faltante | O12: REPITIERON ARQUEO | P12: 16497924
A13: 77 | B13: 5204 | C13: =VLOOKUP(B13,'Lista MF'!B:C,2,0) -> BELLTECH | D13: DIEBOLD | E13: 46084 | F13: 46080 | G13: 10:25:00 | H13: 125379500 | I13: 138577800 | J13: 31520000 | K13: 18321700 | M13: =I13-(H13+J13-K13)-L13 -> 0 | N13: =IF(M13="","",IF(M13=0,"Cuadrado",IF(M13>0,"Faltante","Sobrante"))) -> Cuadrado | O13: Cajero cuadrado, sin observación por parte de la sucursal | P13: 94493031
A14: 115 | B14: 5080 | C14: =VLOOKUP(B14,'Lista MF'!B:C,2,0) -> BELLTECH | D14: BELLTECH | E14: 46084 | F14: 46083 | G14: 09:20:00 | H14: 117021700 | I14: 127700600 | J14: 13120000 | K14: 2441000 | M14: =I14-(H14+J14-K14)-L14 -> -100 | N14: =IF(M14="","",IF(M14=0,"Cuadrado",IF(M14>0,"Faltante","Sobrante"))) -> Sobrante | O14: La diferencia es contabilizada por la Gerencia De Autoservicios y Efectivo de manera centralizada a la cuenta de sobrantes 279510020 el 03/03/2026 | P14: 42158306
A15: 185 | B15: 2208 | C15: =VLOOKUP(B15,'Lista MF'!B:C,2,0) -> DIEBOLD | D15: BELLTECH | E15: 46084 | F15: 46083 | G15: 10:16:00 | H15: 72642500 | I15: 81285500 | J15: 60000 | K15: 1765000 | L15: 8823300 | M15: =I15-(H15+J15-K15)-L15 -> 1524700 | N15: =IF(M15="","",IF(M15=0,"Cuadrado",IF(M15>0,"Faltante","Sobrante"))) -> Faltante | O15: REPITIERON ARQUEO | P15: 66784636
A16: 191 | B16: 5112 | C16: =VLOOKUP(B16,'Lista MF'!B:C,2,0) -> BELLTECH | D16: BELLTECH | E16: 46084 | F16: 46081 | G16: 09:41:00 | H16: 293735350 | I16: 293735350 | J16: 0 | K16: 0 | M16: =I16-(H16+J16-K16)-L16 -> 0 | N16: =IF(M16="","",IF(M16=0,"Cuadrado",IF(M16>0,"Faltante","Sobrante"))) -> Cuadrado | O16: Cajero cuadrado, sin observación por parte de la sucursal | P16: 80812756
A17: 221 | B17: 5221 | C17: =VLOOKUP(B17,'Lista MF'!B:C,2,0) -> BELLTECH | D17: BELLTECH | E17: 46084 | F17: 46081 | G17: 11:48:00 | H17: 110352600 | I17: 174772600 | J17: 64420000 | K17: 0 | M17: =I17-(H17+J17-K17)-L17 -> 0 | N17: =IF(M17="","",IF(M17=0,"Cuadrado",IF(M17>0,"Faltante","Sobrante"))) -> Cuadrado | O17: Cajero cuadrado, sin observación por parte de la sucursal | P17: 52833254
A18: 231 | B18: 6243 | C18: =VLOOKUP(B18,'Lista MF'!B:C,2,0) -> BELLTECH | D18: BELLTECH | E18: 46084 | F18: 46083 | G18: 09:06:00 | H18: 140183150 | I18: 138868150 | J18: 0 | K18: 0 | M18: =I18-(H18+J18-K18)-L18 -> -1315000 | N18: =IF(M18="","",IF(M18=0,"Cuadrado",IF(M18>0,"Faltante","Sobrante"))) -> Sobrante | O18: La diferencia es contabilizada por la Gerencia De Autoservicios y Efectivo de manera centralizada a la cuenta de sobrantes 279510020 el 03/03/2026 | P18: 52979634
A19: 236 | B19: 8497 | C19: =VLOOKUP(B19,'Lista MF'!B:C,2,0) -> BELLTECH | D19: BELLTECH | E19: 46084 | F19: 46083 | G19: 11:23:00 | H19: 91447850 | I19: 328503750 | J19: 25800000 | K19: 67128000 | L19: 281748000 | M19: =I19-(H19+J19-K19)-L19 -> -3364100 | N19: =IF(M19="","",IF(M19=0,"Cuadrado",IF(M19>0,"Faltante","Sobrante"))) -> Sobrante | O19: La diferencia es contabilizada por la Gerencia De Autoservicios y Efectivo de manera centralizada a la cuenta de sobrantes 279510020 el 03/03/2026 | P19: 71369714
A20: 261 | B20: 5048 | C20: =VLOOKUP(B20,'Lista MF'!B:C,2,0) -> BELLTECH | D20: BELLTECH | E20: 46084 | F20: 46083 | G20: 10:53:00 | H20: 289683850 | I20: 234003350 | J20: 12930000 | K20: 54614950 | M20: =I20-(H20+J20-K20)-L20 -> -13995550 | N20: =IF(M20="","",IF(M20=0,"Cuadrado",IF(M20>0,"Faltante","Sobrante"))) -> Sobrante | O20: REPITIERON ARQUEO | P20: 34327627
A21: 262 | B21: 5153 | C21: =VLOOKUP(B21,'Lista MF'!B:C,2,0) -> BELLTECH | D21: BELLTECH | E21: 46084 | F21: 46083 | G21: 10:04:00 | H21: 41691750 | I21: 75511750 | J21: 35520000 | K21: 1700000 | M21: =I21-(H21+J21-K21)-L21 -> 0 | N21: =IF(M21="","",IF(M21=0,"Cuadrado",IF(M21>0,"Faltante","Sobrante"))) -> Cuadrado | O21: Cajero cuadrado, sin observación por parte de la sucursal | P21: 1052378530
A22: 264 | B22: 9906 | C22: =VLOOKUP(B22,'Lista MF'!B:C,2,0) -> BELLTECH | D22: BELLTECH | E22: 46084 | F22: 46083 | G22: 10:18:00 | H22: 61182800 | I22: 63445750 | J22: 23250000 | K22: 20837000 | M22: =I22-(H22+J22-K22)-L22 -> -150050 | N22: =IF(M22="","",IF(M22=0,"Cuadrado",IF(M22>0,"Faltante","Sobrante"))) -> Sobrante | O22: La diferencia es contabilizada por la Gerencia De Autoservicios y Efectivo de manera centralizada a la cuenta de sobrantes 279510020 el 03/03/2026 | P22: 1069722520
A23: 291 | B23: 5114 | C23: =VLOOKUP(B23,'Lista MF'!B:C,2,0) -> BELLTECH | D23: BELLTECH | E23: 46084 | F23: 46080 | G23: 10:44:00 | H23: 129953250 | I23: 145821250 | J23: 29550000 | K23: 13682000 | M23: =I23-(H23+J23-K23)-L23 -> 0 | N23: =IF(M23="","",IF(M23=0,"Cuadrado",IF(M23>0,"Faltante","Sobrante"))) -> Cuadrado | O23: Cajero cuadrado, sin observación por parte de la sucursal | P23: 1095930956
A24: 291 | B24: 5114 | C24: =VLOOKUP(B24,'Lista MF'!B:C,2,0) -> BELLTECH | D24: BELLTECH | E24: 46084 | F24: 46083 | G24: 09:32:00 | H24: 201253250 | I24: 207333250 | J24: 17450000 | K24: 11190000 | M24: =I24-(H24+J24-K24)-L24 -> -180000 | N24: =IF(M24="","",IF(M24=0,"Cuadrado",IF(M24>0,"Faltante","Sobrante"))) -> Sobrante | O24: La diferencia es contabilizada por la Gerencia De Autoservicios y Efectivo de manera centralizada a la cuenta de sobrantes 279510020 el 03/03/2026 | P24: 1095930956
A25: 318 | B25: 5136 | C25: =VLOOKUP(B25,'Lista MF'!B:C,2,0) -> BELLTECH | D25: DIEBOLD | E25: 46084 | F25: 46083 | G25: 08:41:00 | H25: 107378550 | I25: 98473550 | J25: 2870000 | K25: 11300000 | M25: =I25-(H25+J25-K25)-L25 -> -475000 | N25: =IF(M25="","",IF(M25=0,"Cuadrado",IF(M25>0,"Faltante","Sobrante"))) -> Sobrante | O25: La diferencia es contabilizada por la Gerencia De Autoservicios y Efectivo de manera centralizada a la cuenta de sobrantes 279510020 el 03/03/2026 | P25: 1065862494
A26: 318 | B26: 7680 | C26: =VLOOKUP(B26,'Lista MF'!B:C,2,0) -> BELLTECH | D26: BELLTECH | E26: 46084 | F26: 46083 | G26: 09:05:00 | H26: 77044000 | I26: 69364000 | J26: 450000 | K26: 6400000 | M26: =I26-(H26+J26-K26)-L26 -> -1730000 | N26: =IF(M26="","",IF(M26=0,"Cuadrado",IF(M26>0,"Faltante","Sobrante"))) -> Sobrante | O26: La diferencia es contabilizada por la Gerencia De Autoservicios y Efectivo de manera centralizada a la cuenta de sobrantes 279510020 el 03/03/2026 | P26: 1065862494
A27: 322 | B27: 2444 | C27: =VLOOKUP(B27,'Lista MF'!B:C,2,0) -> BELLTECH | D27: BELLTECH | E27: 46084 | F27: 46083 | G27: 09:03:00 | H27: 239919900 | I27: 257059900 | J27: 0 | K27: 0 | M27: =I27-(H27+J27-K27)-L27 -> 17140000 | N27: =IF(M27="","",IF(M27=0,"Cuadrado",IF(M27>0,"Faltante","Sobrante"))) -> Faltante | O27: REPITIERON ARQUEO | P27: 1101320155
A28: 332 | B28: 7569 | C28: =VLOOKUP(B28,'Lista MF'!B:C,2,0) -> BELLTECH | D28: BELLTECH | E28: 46084 | F28: 46083 | G28: 09:35:00 | H28: 15708350 | I28: 216513950 | J28: 0 | K28: 7804400 | L28: 111822000 | M28: =I28-(H28+J28-K28)-L28 -> 96788000 | N28: =IF(M28="","",IF(M28=0,"Cuadrado",IF(M28>0,"Faltante","Sobrante"))) -> Faltante | O28: REPITIERON ARQUEO | P28: 80541675
A29: 348 | B29: 6724 | C29: =VLOOKUP(B29,'Lista MF'!B:C,2,0) -> DIEBOLD | D29: BELLTECH | E29: 46084 | F29: 46083 | G29: 15:25:00 | H29: 65431400 | I29: 105169800 | J29: 21090000 | K29: 82702000 | L29: 105446000 | M29: =I29-(H29+J29-K29)-L29 -> -4095600 | N29: =IF(M29="","",IF(M29=0,"Cuadrado",IF(M29>0,"Faltante","Sobrante"))) -> Sobrante | O29: La diferencia es contabilizada por la Gerencia De Autoservicios y Efectivo de manera centralizada a la cuenta de sobrantes 279510020 el 03/03/2026 | P29: 1123633014
A30: 383 | B30: 5194 | C30: =VLOOKUP(B30,'Lista MF'!B:C,2,0) -> BELLTECH | D30: BELLTECH | E30: 46084 | F30: 46083 | G30: 12:28:41 | H30: 76097750 | I30: 197826150 | J30: 30200000 | K30: 24594000 | M30: =I30-(H30+J30-K30)-L30 -> 116122400 | N30: =IF(M30="","",IF(M30=0,"Cuadrado",IF(M30>0,"Faltante","Sobrante"))) -> Faltante | O30: La diferencia es contabilizada por la Gerencia De Autoservicios y Efectivo de manera centralizada a la cuenta de faltantes 168710093 el 03/03/2026, esta diferencia ingresa a proceso de investigación en el área para identificar a que corresponde. | P30: 1073160492
A31: 395 | B31: 1529 | C31: =VLOOKUP(B31,'Lista MF'!B:C,2,0) -> BELLTECH | D31: BELLTECH | E31: 46084 | F31: 46083 | G31: 09:42:00 | H31: 352278500 | I31: 350070350 | J31: 7850000 | K31: 0 | M31: =I31-(H31+J31-K31)-L31 -> -10058150 | N31: =IF(M31="","",IF(M31=0,"Cuadrado",IF(M31>0,"Faltante","Sobrante"))) -> Sobrante | O31: La diferencia es contabilizada por la Gerencia De Autoservicios y Efectivo de manera centralizada a la cuenta de sobrantes 279510020 el 03/03/2026 | P31: 1121857901
A32: 453 | B32: 8018 | C32: =VLOOKUP(B32,'Lista MF'!B:C,2,0) -> BELLTECH | D32: BELLTECH | E32: 46084 | F32: 46083 | G32: 09:26:00 | H32: 116554650 | I32: 83609650 | J32: 5880000 | K32: 24532000 | M32: =I32-(H32+J32-K32)-L32 -> -14293000 | N32: =IF(M32="","",IF(M32=0,"Cuadrado",IF(M32>0,"Faltante","Sobrante"))) -> Sobrante | O32: REPITIERON ARQUEO | P32: 1083897578
A33: 455 | B33: 5206 | C33: =VLOOKUP(B33,'Lista MF'!B:C,2,0) -> BELLTECH | D33: BELLTECH | E33: 46084 | F33: 46083 | G33: 09:23:00 | H33: 369152000 | I33: 319262200 | J33: 6650000 | K33: 56539800 | M33: =I33-(H33+J33-K33)-L33 -> 0 | N33: =IF(M33="","",IF(M33=0,"Cuadrado",IF(M33>0,"Faltante","Sobrante"))) -> Cuadrado | O33: Cajero cuadrado, sin observación por parte de la sucursal | P33: 1083896352
A34: 457 | B34: 9004 | C34: =VLOOKUP(B34,'Lista MF'!B:C,2,0) -> BELLTECH | D34: DIEBOLD | E34: 46084 | F34: 46083 | G34: 10:43:00 | H34: 292223700 | I34: 232471100 | J34: 7900000 | K34: 59495000 | M34: =I34-(H34+J34-K34)-L34 -> -8157600 | N34: =IF(M34="","",IF(M34=0,"Cuadrado",IF(M34>0,"Faltante","Sobrante"))) -> Sobrante | O34: La diferencia es contabilizada por la Gerencia De Autoservicios y Efectivo de manera centralizada a la cuenta de sobrantes 279510020 el 03/03/2026 | P34: 33750644
A35: 523 | B35: 5082 | C35: =VLOOKUP(B35,'Lista MF'!B:C,2,0) -> BELLTECH | D35: BELLTECH | E35: 46084 | F35: 46083 | G35: 08:50:00 | H35: 199521050 | I35: 200075050 | J35: 1660000 | K35: 1100000 | M35: =I35-(H35+J35-K35)-L35 -> -6000 | N35: =IF(M35="","",IF(M35=0,"Cuadrado",IF(M35>0,"Faltante","Sobrante"))) -> Sobrante | O35: La diferencia es contabilizada por la Gerencia De Autoservicios y Efectivo de manera centralizada a la cuenta de sobrantes 279510020 el 03/03/2026 | P35: 1065609766
A36: 554 | B36: 8294 | C36: =VLOOKUP(B36,'Lista MF'!B:C,2,0) -> BELLTECH | D36: BELLTECH | E36: 46084 | F36: 46083 | G36: 10:34:00 | H36: 209347850 | I36: 219907850 | J36: 10560000 | K36: 0 | M36: =I36-(H36+J36-K36)-L36 -> 0 | N36: =IF(M36="","",IF(M36=0,"Cuadrado",IF(M36>0,"Faltante","Sobrante"))) -> Cuadrado | O36: Cajero cuadrado, sin observación por parte de la sucursal | P36: 1010130794
A37: 554 | B37: 8295 | C37: =VLOOKUP(B37,'Lista MF'!B:C,2,0) -> BELLTECH | D37: BELLTECH | E37: 46084 | F37: 46083 | G37: 15:45:00 | H37: 160173050 | I37: 135761900 | J37: 1000000 | K37: 16603000 | M37: =I37-(H37+J37-K37)-L37 -> -8808150 | N37: =IF(M37="","",IF(M37=0,"Cuadrado",IF(M37>0,"Faltante","Sobrante"))) -> Sobrante | O37: La diferencia es contabilizada por la Gerencia De Autoservicios y Efectivo de manera centralizada a la cuenta de sobrantes 279510020 el 03/03/2026 | P37: 1010130794
A38: 556 | B38: 8333 | C38: =VLOOKUP(B38,'Lista MF'!B:C,2,0) -> BELLTECH | D38: BELLTECH | E38: 46084 | F38: 46081 | G38: 08:55:00 | H38: 232437400 | I38: 252363900 | J38: 31530000 | K38: 11603500 | M38: =I38-(H38+J38-K38)-L38 -> 0 | N38: =IF(M38="","",IF(M38=0,"Cuadrado",IF(M38>0,"Faltante","Sobrante"))) -> Cuadrado | O38: Cajero cuadrado, sin observación por parte de la sucursal | P38: 39450196
A39: 613 | B39: 6713 | C39: =VLOOKUP(B39,'Lista MF'!B:C,2,0) -> DIEBOLD | D39: BELLTECH | E39: 46084 | F39: 46083 | G39: 09:43:00 | H39: 113270800 | I39: 110824100 | J39: 14050000 | K39: 16111300 | M39: =I39-(H39+J39-K39)-L39 -> -385400 | N39: =IF(M39="","",IF(M39=0,"Cuadrado",IF(M39>0,"Faltante","Sobrante"))) -> Sobrante | O39: La diferencia es contabilizada por la Gerencia De Autoservicios y Efectivo de manera centralizada a la cuenta de sobrantes 279510020 el 03/03/2026 | P39: 32106943
A40: 634 | B40: 5087 | C40: =VLOOKUP(B40,'Lista MF'!B:C,2,0) -> BELLTECH | D40: BELLTECH | E40: 46084 | F40: 46083 | G40: 09:04:00 | H40: 242530800 | I40: 254556300 | J40: 12040000 | K40: 0 | M40: =I40-(H40+J40-K40)-L40 -> -14500 | N40: =IF(M40="","",IF(M40=0,"Cuadrado",IF(M40>0,"Faltante","Sobrante"))) -> Sobrante | O40: La diferencia es contabilizada por la Gerencia De Autoservicios y Efectivo de manera centralizada a la cuenta de sobrantes 279510020 el 03/03/2026 | P40: 1032424944
...

Sheet Lista MF
A1: Cod Suc | B1: Cajero | C1: Marca | D1: Cajero | E1: Sucursal | F1: Lider de servicio | G1: SUBGERENTE | H1: FECHA ARQUEO | I1: FECHA REPROGRAMACION | J1: FECHA PROGRAMADA | K1: OBSERVACIÓN
A2: 348 | B2: 192 | C2: BELLTECH | D2: Multifuncional | E2: SAN ANDRES | F2: Didi Alejandra Pareja Medina | G2: PPOLO | H2: 46093 | K2: Nuevo 31 Julio, Sin servicio
A3: 333 | B3: 442 | C3: DIEBOLD | D3: Multifuncional | E3: SABANETA AVES MARIA | F3: Sandra Milena Cardona Franco | G3: LUCRAMIR | H3: 46086 | K3: Nuevo 31 Julio, Sin servicio
A4: 331 | B4: 574 | C4: BELLTECH | D4: Multifuncional | E4: ARKADIA | F4: Ana Maria Echavarria Gonzalez | G4: NDUQUE | H4: 46086
A5: 331 | B5: 575 | C5: BELLTECH | D5: Multifuncional | E5: ARKADIA | F5: Ana Maria Echavarria Gonzalez | G5: NDUQUE | H5: 46086
A6: 61 | B6: 788 | C6: BELLTECH | D6: Multifuncional | E6: CENTRO COMERCIAL LA ESTACIÓN CALI | F6: Hector Mario Rendon Ocampo | G6: MOCANO | H6: 46091 | K6: 09 de Sep inicia a ser de suc
A7: 287 | B7: 907 | C7: DIEBOLD | D7: Multifuncional | E7: CENTRAL DE ABASTOS B/MANGA | F7: Yenis Meybi Fernandez Marin | G7: LMPINILL | H7: 46100 | K7: instalan cajero 20 de enero
A8: 481 | B8: 1010 | C8: BELLTECH | D8: Multifuncional | E8: SOLEDAD | F8: German Alcides Hernandez Vivero | G8: VAESTRAD | H8: 46091
A9: 481 | B9: 1011 | C9: BELLTECH | D9: Multifuncional | E9: SOLEDAD | F9: German Alcides Hernandez Vivero | G9: VAESTRAD | H9: 46091
A10: 795 | B10: 1027 | C10: BELLTECH | D10: Multifuncional | E10: CAÑAVERAL | F10: Yenis Meybi Fernandez Marin | G10: CEAUARIA | H10: 46091 | I10: =VLOOKUP(A10,[1]Programación!$A:$J,10,0) -> 2 Días
A11: 795 | B11: 1028 | C11: BELLTECH | D11: Multifuncional | E11: CAÑAVERAL | F11: Yenis Meybi Fernandez Marin | G11: CEAUARIA | H11: 46091 | I11: =VLOOKUP(A11,[1]Programación!$A:$J,10,0) -> 2 Días
A12: 795 | B12: 1029 | C12: BELLTECH | D12: Multifuncional | E12: CAÑAVERAL | F12: Yenis Meybi Fernandez Marin | G12: CEAUARIA | H12: 46091 | I12: =VLOOKUP(A12,[1]Programación!$A:$J,10,0) -> 2 Días
A13: 745 | B13: 1477 | C13: BELLTECH | D13: Multifuncional | E13: MALLPLAZA CALI | F13: Hector Mario Rendon Ocampo | G13: MCORRALE | H13: 46091
A14: 377 | B14: 1508 | C14: DIEBOLD | D14: Multifuncional | E14: AVENTURA CENTRO COMERCIAL | F14: Katherine Zapata Cano | G14: CAALJARA | H14: 46086
A15: 692 | B15: 1515 | C15: BELLTECH | D15: Multifuncional | E15: ALTO PRADO | F15: Maria Teresa Chaves Ahumada | G15: FLOZANO | H15: 46091 | K15: NUEVO, DESDE EL 7 DE ENERO
A16: 692 | B16: 1516 | C16: BELLTECH | D16: Multifuncional | E16: ALTO PRADO | F16: Maria Teresa Chaves Ahumada | G16: FLOZANO | H16: 46091 | K16: NUEVO, DESDE EL 7 DE ENERO
A17: 395 | B17: 1528 | C17: BELLTECH | D17: Multifuncional | E17: VIVA VILLAVICENCIO | F17: Juan Felipe Russi Gamboa | G17: LJROMERO | H17: 46091 | I17: =VLOOKUP(A17,[1]Programación!$A:$J,10,0) -> 2 Días
A18: 395 | B18: 1529 | C18: BELLTECH | D18: Multifuncional | E18: VIVA VILLAVICENCIO | F18: Juan Felipe Russi Gamboa | G18: LJROMERO | H18: 46091 | I18: =VLOOKUP(A18,[1]Programación!$A:$J,10,0) -> 2 Días
A19: 141 | B19: 1541 | C19: BELLTECH | D19: Multifuncional | E19: MERCANTIL | F19: Victoria Eugenia Guaqueta Murcia | G19: DICARDEN | H19: 46099
A20: 438 | B20: 1565 | C20: BELLTECH | D20: Multifuncional | E20: ANDES | F20: Sandra Milena Cardona Franco | G20: JOGRESTR | H20: 46100
A21: 944 | B21: 2228 | C21: BELLTECH | D21: Multifuncional | E21: CENTRO COMERCIAL SANTAFE | F21: Nidya Marcela Poveda Sanchez | G21: SBOHORQU | H21: 46098 | K21: 9 Julio consola
A22: 108 | B22: 2254 | C22: DIEBOLD | D22: Multifuncional | E22: PLAZA DE LAS AMERICAS | F22: Samuel Alexander Mendez Suarez | G22: SMALVARA | H22: 46099
A23: 322 | B23: 2444 | C23: BELLTECH | D23: Multifuncional | E23: SAN GIL | F23: Frank William Castillo Leal | G23: CARLBALL | H23: 46093
A24: 907 | B24: 4830 | C24: BELLTECH | D24: Multifuncional | E24: LA FRONTERA | F24: Natalia Zuluaga Rodriguez | G24: MARIADAG | H24: 46093 | K24: Nuevo 24 Junio
A25: 5 | B25: 4866 | C25: DIEBOLD | D25: Multifuncional | E25: ATM MF SUCAVENIDA EL POBLADO 1 | F25: Natalia Zuluaga Rodriguez | G25: PCVARGAS | H25: 46099 | K25: Nuevo 26 de agosto, Sin servicio
A26: 777 | B26: 4868 | C26: DIEBOLD | D26: Multifuncional | E26: PARQUE WASHINGTON | F26: Maria Teresa Chaves Ahumada | G26: FRICAURT | H26: 46092 | K26: Provisionar con 9 millones y el cajero no funcionó
A27: 1 | B27: 5000 | C27: BELLTECH | D27: Multifuncional | E27: CARABOBO | F27: Katherine Zapata Cano | G27: FLLOPEZ | H27: 46086
A28: 6 | B28: 5001 | C28: BELLTECH | D28: Multifuncional | E28: AVENIDA JUNIN | F28: Katherine Zapata Cano | G28: DJMONTOY | H28: 46086 | I28: =VLOOKUP(A28,[1]Programación!$A:$J,10,0) -> 2 Días
A29: 59 | B29: 5002 | C29: BELLTECH | D29: Multifuncional | E29: AVENIDA SANTANDER | F29: Sergio Arias Pelaez | G29: CVALASQU | H29: 46100
A30: 361 | B30: 5005 | C30: BELLTECH | D30: Multifuncional | E30: CENTRO DE PAGOS FONTIBON | F30: Fabio Orlando Bosa Poveda | G30: jaolarte | H30: 46092
A31: 777 | B31: 5009 | C31: BELLTECH | D31: Multifuncional | E31: PARQUE WASHINGTON | F31: Maria Teresa Chaves Ahumada | G31: FRICAURT | H31: 46092
A32: 779 | B32: 5013 | C32: BELLTECH | D32: Multifuncional | E32: BUENAVISTA SANTA MARTA | F32: Alicia Minerva Fontalvo Reales | G32: MAVERGAR | H32: 46100
A33: 907 | B33: 5019 | C33: BELLTECH | D33: Multifuncional | E33: LA FRONTERA | F33: Natalia Zuluaga Rodriguez | G33: MARIADAG | H33: 46093
A34: 882 | B34: 5020 | C34: BELLTECH | D34: Multifuncional | E34: LIBERTADORES | F34: Yury Yaquelin Daza Congo | G34: YPARRA | H34: 46093 | I34: =VLOOKUP(A34,[1]Programación!$A:$J,10,0) -> 2 Días
A35: 277 | B35: 5021 | C35: BELLTECH | D35: Multifuncional | E35: CENTRO COMERCIAL MAYORCA | F35: Sandra Milena Cardona Franco | G35: LMCALZAT | H35: 46092
A36: 825 | B36: 5023 | C36: BELLTECH | D36: Multifuncional | E36: ASTROCENTRO | F36: Hector Mario Rendon Ocampo | G36: JHAMAYA | H36: 46086 | I36: =VLOOKUP(A36,[1]Programación!$A:$J,10,0) -> 2 Días
A37: 32 | B37: 5027 | C37: BELLTECH | D37: Multifuncional | E37: ANTIGUO COUNTRY | F37: Kirsys Nadyra Robelto Sanchez | G37: SANDGARC | H37: 46093
A38: 167 | B38: 5030 | C38: BELLTECH | D38: Multifuncional | E38: AVENIDA 82 | F38: Kirsys Nadyra Robelto Sanchez | G38: MARIMOSQ | H38: 46092
A39: 275 | B39: 5034 | C39: BELLTECH | D39: Multifuncional | E39: BOULEVAR ENVIGADO | F39: Sandra Milena Cardona Franco | G39: DIBLANDO | H39: 46086
A40: 81 | B40: 5036 | C40: BELLTECH | D40: Multifuncional | E40: AVENIDA KENNEDY | F40: German Alcides Hernandez Vivero | G40: JAMESA | H40: 46091
...

Sheet Notas
A2: Pendiente de investigación por parte de la Sección Servicios Sucursales
A3: Pendiente de investigación por parte de la Sucursal | B3: ACLARAR DIFERENCIA Y REPETIR ARQUEO, por favor validar provisiones trocadas entre los cajeros 4517 y 4847, contactarme por teams una vez hayan encontrado el error para indicarles cómo proceder.
B5: ACLARAR DIFERENCIA Y REPETIR EL ARQUEO
B6: Cajero cuadrado, sin observación por parte de la sucursal.
A7: Contabilizada por la sección en la cuenta de Faltantes 168710093 el 16/12/2022 - Faltante queda en investigación por parte de la Sección Serv. Sucursales. | B7: La diferencia es contabilizada por la Gerencia De Autoservicios y Efectivo de manera centralizada a la cuenta de faltantes 168710093 el 04/03/2026, esta diferencia ingresa a proceso de investigación en el área para identificar a que corresponde.
A8: Contabilizada por la sección en la cuenta de Faltantes 168710093 el 27/12/2021 - REVERSAR | B8: La diferencia es contabilizada por la Gerencia De Autoservicios y Efectivo de manera centralizada a la cuenta de sobrantes 279510020 el 05/03/2026
A9: Faltante originado por sobrante contabilizado el 08/12/2021 - Se reversa el 27/12/2021 | B9: El sobrante es cruzado con faltante contabilizado el 26/01/2026 el cual es reversado por la Gerencia De Autoservicios y Efectivo el 12/02/2026
A10: Diferencia menor a 3.000 - No es necesario otro arqueo | B10: Faltante es reversado por la sección el 03 de abril, con sobrante contabilizado el día 20 de marzo
A11: Aclarar Diferencia. En caso de no aclarar por favor realizar un nuevo arqueo al cajero. | B11: El faltante de $26.000 es cruzado con sobrante contabilizado el día 11/02/2026 el cual es reversado por la seccion el día 16/02/2026
A12: Aclarar Diferencia, realizar las validaciones indicadas en el correo de Faltantes. En caso de no aclarar por favor realizar un nuevo arqueo al cajero. | B12: El sobrante es cruzado con faltante contabilizado el día 28/09/2025 el cual es reversado por la seccion el día 11/09/2025, la diferencia es contabilizada por la sección en la cuenta 279510020 el día 11/09/2025
A13: REVERSAR | B13: El faltante $46.600 es cruzado con sobrante contabilizado el día 23/02/2026 el cual es reversado por la seccion el día 28/02/2026
A14: Cuadrado
A17: *CANCELACION FALTANTES CUENTA 168710093 POR PARTE DE LAS SUCURSALES*
A18: TRX MEDELLIN: 2492 Para cancelar (pagar) los faltantes que tengan contabilizados en la cuenta 168710093, realizan en Medellín la transacción 2492 con código cajero MF y la cédula del cajero a quien fue cargado el faltante en su momento. Esta Trx les da cruce a caja con entrada de efectivo. NOTA: Antes de realizar la cancelación por favor verificar siempre la cuenta 168710093.
A20: CONTABILIDADES GOLF-WOLF SUCURSALES
A21: 0041 - Provisión Cajero Wolf - Seleccionan la TX realizada y en recuadro abajo dan la opción "Reversar"
A22: 0105 - Remanente Cajero Wolf - Sucursal
A23: 0095 - Faltantes en Caja
A24: 0097 - Sobrantes en Caja
A25: 0096 - Reintegro Faltantes en Caja
A27: Deben reintegrar el sobrante de caja y meterlo físico al cajero XXX, al cajero NO se le hace nada contable, solo ingresarle de manera física el dinero y deben realizarle nuevamente arqueo al cajero y ya este se debe reflejar cuadrado con el ajuste realizado.
A30: billetes falsos en cajero mf belltech, deben de hacer arqueo sin tener en cuenta el billete primero porque puede que el cajero reciba el dinero pero no haga ninguna trx y no genere descuadre, si el cajero genera descuadre deben de sacar el billete como remanente, grabar faltante en caja, enviarnos un correo para reclasificarlo a faltantes cajero y llevarlo al pyg y enviar el billete a la sección
G611: 0.39791667

Sheet CP
A1: CODIGO | B1: COD. SUC | C1: CODIGO | D1: Dispensador / Multifuncional | E1: ADMINISTRACIÓN | F1: MARCA
A2: 574 | B2: 331 | C2: 574 | D2: Multifuncional | E2: SUC | F2: BELLTECH
A3: 575 | B3: 331 | C3: 575 | D3: Multifuncional | E3: SUC | F3: BELLTECH
A4: 788 | B4: 61 | C4: 788 | D4: Multifuncional | E4: SUC | F4: BELLTECH
A5: 907 | B5: 287 | C5: 907 | D5: Multifuncional | E5: SUC | F5: DIEBOLD
A6: 1010 | B6: 481 | C6: 1010 | D6: Multifuncional | E6: SUC | F6: BELLTECH
A7: 1011 | B7: 481 | C7: 1011 | D7: Multifuncional | E7: SUC | F7: BELLTECH
A8: 1027 | B8: 795 | C8: 1027 | D8: Multifuncional | E8: SUC | F8: BELLTECH
A9: 1028 | B9: 795 | C9: 1028 | D9: Multifuncional | E9: SUC | F9: BELLTECH
A10: 1029 | B10: 795 | C10: 1029 | D10: Multifuncional | E10: SUC | F10: BELLTECH
A11: 1477 | B11: 745 | C11: 1477 | D11: Multifuncional | E11: SUC | F11: BELLTECH
A12: 1508 | B12: 377 | C12: 1508 | D12: Multifuncional | E12: SUC | F12: DIEBOLD
A13: 1515 | B13: 692 | C13: 1515 | D13: Multifuncional | E13: SUC | F13: BELLTECH
... A36: 5041 | B36: 154 | C36: 5041 | D36: Multifuncional | E36: SUC | F36: BELLTECH
A37: 5043 | B37: 867 | C37: 5043 | D37: Multifuncional | E37: SUC | F37: BELLTECH
A38: 5045 | B38: 879 | C38: 5045 | D38: Multifuncional | E38: SUC | F38: BELLTECH
A39: 5046 | B39: 723 | C39: 5046 | D39: Multifuncional | E39: SUC | F39: BELLTECH
A40: 5047 | B40: 623 | C40: 5047 | D40: Multifuncional | E40: SUC | F40: BELLTECH
A41: 5048 | B41: 261 | C41: 5048 | D41: Multifuncional | E41: SUC | F41: BELLTECH
A42: 5049 | B42: 682 | C42: 5049 | D42: Multifuncional | E42: SUC | F42: BELLTECH
A43: 5050 | B43: 852 | C43: 5050 | D43: Multifuncional | E43: SUC | F43: BELLTECH
A44: 5051 | B44: 769 | C44: 5051 | D44: Multifuncional | E44: SUC | F44: BELLTECH
A45: 5052 | B45: 916 | C45: 5052 | D45: Multifuncional | E45: SUC | F45: BELLTECH
A46: 5053 | B46: 517 | C46: 5053 | D46: Multifuncional | E46: SUC | F46: BELLTECH
A47: 5057 | B47: 781 | C47: 5057 | D47: Multifuncional | E47: SUC | F47: BELLTECH
A48: 5059 | B48: 7 | C48: 5059 | D48: Multifuncional | E48: SUC | F48: BELLTECH
A49: 5064 | B49: 392 | C49: 5064 | D49: Multifuncional | E49: SUC | F49: BELLTECH
... A76: 5128 | B76: 101 | C76: 5128 | D76: Multifuncional | E76: SUC | F76: BELLTECH
A77: 5129 | B77: 244 | C77: 5129 | D77: Multifuncional | E77: SUC | F77: BELLTECH
A78: 5132 | B78: 366 | C78: 5132 | D78: Multifuncional | E78: SUC | F78: BELLTECH
A79: 5135 | B79: 68 | C79: 5135 | D79: Multifuncional | E79: SUC | F79: BELLTECH
A80: 5136 | B80: 318 | C80: 5136 | D80: Multifuncional | E80: SUC | F80: BELLTECH
A81: 5137 | B81: 829 | C81: 5137 | D81: Multifuncional | E81: SUC | F81: BELLTECH
A82: 5139 | B82: 300 | C82: 5139 | D82: Multifuncional | E82: SUC | F82: BELLTECH
A83: 5141 | B83: 53 | C83: 5141 | D83: Multifuncional | E83: SUC | F83: BELLTECH
A84: 5142 | B84: 40 | C84: 5142 | D84: Multifuncional | E84: SUC | F84: BELLTECH
A85: 5143 | B85: 927 | C85: 5143 | D85: Multifuncional | E85: SUC | F85: BELLTECH
A86: 5144 | B86: 812 | C86: 5144 | D86: Multifuncional | E86: SUC | F86: BELLTECH
A87: 5147 | B87: 279 | C87: 5147 | D87: Multifuncional | E87: SUC | F87: BELLTECH
A88: 5148 | B88: 91 | C88: 5148 | D88: Multifuncional | E88: SUC | F88: BELLTECH
...

Sheet Hoja1
A1: Cod Suc | B1: Cajero | C1: Marca | D1: Cajero | E1: Sucursal | F1: Lider de servicio | G1: SUBGERENTE | H1: FECHA ARQUEO | I1: FECHA REPROGRAMACION | J1: FECHA PROGRAMADA | K1: OBSERVACIÓN
A2: 361 | B2: 5005 | C2: BELLTECH | D2: Multifuncional | E2: CENTRO DE PAGOS FONTIBON | F2: Fabio Orlando Bosa Poveda | G2: jaolarte | H2: 46070
